Workbook

Sheet NVScriptsProperties
A1: autocratn | B1: autocratp
A2: dataSheetName | B2: "Respostas ao formulário 1"
A3: v | B3: "5.1"
A4: dataSheetId | B4: "4.6943552E7"
A5: updateTime | B5: "1.695293575079E12"
A6: vp | B6: "5.1"
A7: ssId | B7: "1EOfkNmt2F3RK-WIEaEhvcUSwhmj9TqNS6JDS_CQSkT8"

Sheet Respostas ao formulário 1
A1: Local | B1: Alimentação (Telemetria) | C1: PLC | D1: No Break | E1: Comunicação | F1: Redundância | G1: DPS | H1: Fusível | I1: Conversor | J1: Marca da fonte | K1: Tipo | L1: Tensão | M1: Driver 1 - Tipo | N1: Driver 1 - Serial | O1: Driver 2 - Tipo | P1: Driver 2 - Serial | Q1: Driver 3 - Tipo | R1: Driver 3 - Serial | S1: Driver 4 - Tipo | T1: Driver 4 - Serial | U1: Potência | V1: Tensão (V) | W1: Corrente (A) | X1: RPM | Y1: FS | Z1: Acionamento | AA1: Potência | AB1: Tensão (V) | AC1: Corrente (A) | AD1: RPM | AE1: FS | AF1: Acionamento | AG1: Potência | AH1: Tensão (V) | AI1: Corrente (A) | AJ1: RPM | AK1: FS | AL1: Acionamento | AM1: Modelo/Fabricante | AN1: Vazão (m^3/h) | AO1: Altura Manométrica (mca) | AP1: Vazão (l/s) | AQ1: Modelo/Fabricante | AR1: Vazão (m^3/h) | AS1: Altura Manométrica (mca) | AT1: Vazão (l/s) | AU1: Sucção 1 | AV1: Recalque 1 | AW1: Recalque 2 | AX1: Recalque 3 | AY1: Tipo do sensor | AZ1: Vazão 1 - Fabricante | BA1: Vazão 1 - Modelo do Conversor | BB1: Vazão 1 - Serial do Conversor | BC1: Vazão 1 - Modelo do Sensor | BD1: Vazão 1 - Diâmetro Nominal | BE1: Vazão 1 - Fator k/kp | BF1: Vazão 1 - Fator kA | BG1: Vazão 1 - Fundo de Escala | BH1: Tipo do sensor | BI1: Vazão 2 - Fabricante | BJ1: Vazão 2 - Modelo do Conversor | BK1: Vazão 2 - Serial do Conversor | BL1: Vazão 2 - Modelo do Sensor | BM1: Vazão 2 - Diâmetro Nominal | BN1: Vazão 2 - Fator k/kp | BO1: Vazão 2 - Fator kA | BP1: Vazão 2 - Fundo de Escala | BQ1: Tipo do sensor | BR1: Vazão 3 - Fabricante | BS1: Vazão 3 - Modelo do Conversor | BT1: Vazão 3 - Serial do Conversor | BU1: Vazão 3 - Modelo do Sensor | BV1: Vazão 3 - Diâmetro Nominal | BW1: Vazão 3 - Fator k/kp | BX1: Vazão 3 - Fator kA | BY1: Vazão 3 - Fundo de Escala | BZ1: Tipo do sensor | CA1: Altura total (m) | CB1: Altura do 0% (4mA) | CC1: Altura do 100% (20mA) | CD1: Observações
A2: Aeroporto (Reservatório) | B2: Energia Solar | C2: Sem PLC | D2: Não tem | E2: Modem ABS | F2: Sem Redundância | H2: Simens 10A 500V | K2: 7 - Reservatório | BZ2: Nivelco Configurável
A3: Alegria do Boi | B3: 127V | C3: Sem PLC | D3: Não tem | E3: Modem ABS | F3: Sem Redundância | J3: Conexel | K3: 10 - Vazão com VRP | AU3: 0 a 200 MCA | AV3: 0 a 200 MCA | AY3: Carretél | AZ3: Isoil | BA3: MV110 | BB3: ABV007408
A4: Alfineiros | B4: 127V | C4: Altus Duo, 245794 | D4: Não tem | E4: Modem ABS | F4: Sem Redundância | G4: Lupa | H4: NH1 80A 690V | J4: Weidmuller | K4: 1 - Booster | L4: 220V | M4: CFW110086T2OFAZ | N4: 1032791007 | U4: 15CV | V4: 220V | W4: 37.6A | X4: 1760 | Y4: 1.25 | Z4: Driver 1 | AA4: 15CV | AB4: 220V | AC4: 37.6A | AD4: 1760 | AE4: 1.25 | AF4: Driver 1 | AM4: KSB MULTITEC 65/05 C | AQ4: KSB MULTITEC 65/05 C | AU4: Zurich - 0 a 70 MCA | AV4: Zurich - 0 a 200 MCA | AY4: Carretél | AZ4: Isoil | BA4: MV110 | BB4: ABV005986 | BC4: MS 1000-P100-1A2A
A5: Alphaville (ETE) (Tanque A) | B5: 127V | C5: Altus Duo, 4155893T | D5: NHS Compact Plus III | E5: Modem ABS | F5: Sem Redundância | G5: Clamper | H5: NH 50A 500V/ 25A 690V | K5: 3 - Elevatória de Esgoto | L5: 220V | M5: CFW110016T2SZ | N5: 1054457538 | O5: Vacon | P5: V00000281594 | AY5: Carrétel | AZ5: Danfoss | BA5: M100 | BB5: D6100247 | BZ5: Ultrassônico Nivelco - 0 a 5 m | CD5: Elevatória 4 (fundo, canto direito)
A6: Alphaville 4B | B6: 127V | C6: Altus Duo, 415887T | D6: NHS Compact Plus III | G6: Clamper | H6: NH000 50A 500V/ NH00 25A 690V | J6: Altus | K6: 3 - Elevatória de Esgoto | L6: 220V | M6: Vacon | N6: V0000029518 | O6: Vacon | P6: V00000282884 | AY6: Carrétel | AZ6: Danfoss | BA6: M100 | BB6: D6100257 | BZ6: Ultrassônico Nivelco - 0 a 5 m
A7: Alphaville 5 (Esgoto) | B7: 127V | C7: Altus Duo, 415884T | D7: NHS Compact Plus III | F7: Sem Redundância | G7: Clamper | H7: NH00 50A 500V/ 40A 690V | J7: Altus | K7: 3 - Elevatória de Esgoto | L7: 220V | M7: Altus | N7: V00000282903 | O7: Altus | P7: V00000281616 | AY7: Carrétel | AZ7: Danfoss | BA7: M100 | BB7: D6100256 | BZ7: Ultrassônico Nivelco - 0 a 5 m | CD7: Elevatória 5 (esquerda)
A8: Alphaville Elevado | B8: 127V | C8: Altus Duo, 599041 | D8: NHS Compact Plus III | E8: Modem ABS | F8: Sem Redundância | G8: Lupa | H8: NH00 50A 500V | J8: Altus | K8: 8 - Reservatório com elevatória | L8: 220V | M8: Altus | N8: V00000298525 | O8: Altus | P8: V00000834803 | U8: 4CV | V8: 220V | W8: 10.9A | X8: 3475 | Y8: 1.25 | Z8: Driver 1 | AA8: 4CV | AB8: 220V | AC8: 10.9A | AD8: 3475 | AE8: 1.25 | AF8: Driver 2 | AM8: KSB MEGABLOC 50-32-125 GG | AN8: 20 | AO8: 25 | AQ8: KSB MEGABLOC 50-32-125 GG | AR8: 20 | AS8: 25 | AV8: Simens - Janela | BZ8: Ultrassônico Nivelco - 0 a 5 m
A9: Alphaville Esgoto 01 | B9: 127V | C9: Altus Duo, 415896T | D9: NHS Compact Plus III | E9: Modem ABS | F9: Sem Redundância | G9: Lupa | H9: NH00 63A 500V/ NH00 50A 690V | J9: Altus AL 1535 | K9: 3 - Elevatória de Esgoto | L9: 220V | M9: CFW110033T2OFAZ | N9: 1067477787 | O9: Vacon | P9: V00000298526 | U9: 7,5CV | V9: 230V | W9: 19A | X9: 1770 | Z9: Driver 1 | AA9: 7,5CV | AB9: 230V | AC9: 19A | AD9: 1770 | AF9: Driver 2 | AM9: FLYGT MODELO 3127-170 | AN9: 300 | AO9: 6 | AQ9: FLYGT MODELO 3127-170 | AR9: 300 | AS9: 6 | AY9: Carrétel | AZ9: Danfoss | BA9: M100 | BB9: D6100248 | BZ9: Ultrassônico Nivelco - 0 a 5 m
A10: Alphaville Esgoto 2 | B10: 127V | C10: Altus Duo, 566938 | D10: NHS Compact Plus III | E10: Modem ABS | F10: Sem Redundância | G10: Lupa | H10: NH00 160A 500V / NH00 125A 690V | J10: Altus | K10: 3 - Elevatória de Esgoto | L10: 220V | M10: Vacon | N10: V00000284641 | O10: Vacon | P10: V00000284641 | Q10: CFW110105T2OFAZ | R10: 1067388642 | U10: 22kW | V10: 220V | W10: 73A | X10: 1465 | Z10: Driver 1 | AA10: 22kW | AB10: 220V | AC10: 73A | AD10: 1465 | AF10: Driver 2 | AM10: KSB KRT K80 315/232 XG | AN10: 61 | AO10: 54 | BZ10: Ultrassônico Nivelco - 0 a 5 m
A11: Alphaville Esgoto 3 | B11: 127V | C11: Altus Duo, 599044 | D11: Engetron | E11: Modem ABS | F11: Sem Redundância | G11: Lupa | H11: NH00 50A 500V | J11: Altus | K11: 3 - Elevatória de Esgoto | L11: 220V | M11: Vacon | N11: V00000281615 | O11: CFW110024T2OFAZ | P11: 1032950773 | BZ11: Ultrassônico Nivelco - 0 a 5 m
A12: Alphaville Principal | B12: 127V | C12: Altus Duo, 421851T | D12: NHS Compact Plus III | E12: Modem ABS | F12: Sem Redundância | G12: Lupa | H12: NH00 125A 500V | I12: ADM 4541 - Rs 232/485 | J12: Altus | K12: 2 - Elevatória de Água | L12: 220V | M12: Altus | N12: V00000282542 | O12: Altus | P12: V00000284634 | U12: 30CV | V12: 220V | W12: 72.2A | X12: 3535 | Y12: 1.15 | Z12: Driver 1 | AA12: 30CV | AB12: 220V | AC12: 72.2A | AD12: 3535 | AE12: 1.15 | AF12: Driver 1 | AM12: FLOWSERVE DBE | AQ12: FLOWSERVE DBE | AU12: Simens Janela | AV12: Simens Janela | AZ12: Simens F M | BA12: MAG 5000 | BB12: 7ME69101AA101AA0 | CD12: Sucção: Simens -1-32 bar (overrange limits)/ -0.16-16(meansuring span) Recalque: Simens -1-100 bar (overrange limits)/ -0.63-63 (meansuring span)
A13: Alto Bairu | B13: 127V | C13: Altus Duo, 266843 | D13: Não tem | E13: Modem ABS | F13: Fibra | G13: Lupa | I13: Alphacomp CS Ethernet, Alphacomp RS 232 - RS 485, Novus Digirail mA - RS 485, Clamper série 900 | J13: Weg | K13: 8 - Reservatório com elevatória | L13: 200V | M13: Partida Direta | U13: 3CV | V13: 220V | W13: 7.5A | X13: 3450 | Y13: 1.15 | Z13: Driver 1 | AA13: 3CV | AB13: 220V | AC13: 7.5A | AD13: 3450 | AE13: 1.15 | AF13: Driver 1 | AU13: Zurich - 0 a 70 MCA | AV13: Conect - 0 a 100 MCA | AY13: Carretél | AZ13: Indflow | BA13: BLIT-EM | BB13: 1000328 | BH13: Carretél | BI13: Indflow | BJ13: BLIT-EM | BK13: 1000367 | BZ13: Pressão | CD13: Conect JCO 0 a 100mca (recalque)
A14: Alto dos Pinheiros (Elevatória) | B14: 127V | C14: Sem PLC | D14: Não tem | F14: Sem Redundância | H14: NH00 400A 690V | K14: 2 - Elevatória de Água | L14: 220V | M14: CFW110180T2SZ | N14: 1050963401 | U14: 75CV | V14: 220V | W14: 171A | X14: 3560 | Y14: 1.15 | Z14: Driver 1 | AA14: 75CV | AB14: 220V | AC14: 175A | AD14: 1770 | AE14: 1.15 | AF14: Driver 1
A15: Alto Santo Antônio | B15: 127V | C15: Altus Duo, 601789 | D15: Não tem | E15: Modem ABS | F15: Sem Redundância | G15: Lupa | J15: Weidmuller | K15: 8 - Reservatório com elevatória | L15: 200V | M15: Partida Direta | U15: 3CV | V15: 220V | W15: 8.42A | X15: 3465 | Y15: 1.15 | Z15: Driver 1 | AA15: 3CV | AB15: 220V | AC15: 8.42A | AD15: 3465 | AE15: 1.15 | AF15: Driver 1 | AU15: SMAR - Janela | BZ15: Pressão
A16: Alto Santo Antônio (Elevatória)/Retiro | B16: 127V | H16: NH1 200A 500V | K16: 2 - Elevatória de Água | L16: 220V | M16: Soft Ssw 03 | O16: CFW110105T2OFAZ | P16: 1035540477 | U16: 40CV | V16: 220V | W16: 99A | X16: 3560 | Y16: 1.25 | Z16: Driver 1 | AA16: 40CV | AB16: 220V | AC16: 99A | AD16: 3560 | AE16: 1.25 | AF16: Driver 2 | AV16: Zurich - 0 a 200 MCA | AY16: Carretél | AZ16: Isoil | BA16: MV110 | BB16: ABZ003322 | CD16: Mesmo local Elevatória Retiro
A17: Alvim (Elevatória) | B17: 127V | C17: Altus Duo, 245822 | D17: Não tem | E17: Modem ABS | F17: Sem Redundância | G17: Clamper | H17: NH00 63A 690V | J17: Conexel | K17: 2 - Elevatória de Água | L17: 220V | M17: CFW110024T2OFAZ | N17: 1067450220 | U17: 7.5 CV | V17: 220V | W17: 19.4A | X17: 3515 | Y17: 1.25 | Z17: Driver 1 | AA17: 7.5CV | AB17: 220V | AC17: 19.4A | AD17: 3515 | AE17: 1.25 | AF17: Driver 1 | AM17: VME-9875 7.5 T 60 4V | AN17: 3.5 min/ 18.1 max | AO17: 38 min /132max | AQ17: VME-9875 7.5 T 60 4V | AR17: 3.5 min/ 18.1 max | AS17: 38 min/ 132 max | AU17: Sem sucção | AV17: Zurich - 0 a 200 MCA
A18: Amazonas (Elevatória) | B18: 127V | C18: Altus Duo, 604632 | D18: Não tem | E18: Modem LUPA | F18: Sem Redundância | G18: Lupa | H18: NH00 80A 690V | J18: LR Informática | K18: 2 - Elevatória de Água | L18: 220V | M18: CFW110054T2OFAZ | N18: 1039442998 | U18: 12.5CV | V18: 220V | W18: 29.8A | X18: 3530 | Y18: 1.25 | Z18: Driver 1 | AA18: 12.5CV | AB18: 220V | AC18: 29.8A | AD18: 3530 | AE18: 1.25 | AF18: Driver 1 | AM18: KSB METB 65-40-150 GG | AN18: 33.96 | AO18: 49.96 | AQ18: KSB METB 65-40-160 GG | AR18: 33.96 | AS18: 49.96 | AU18: Zurich - 0 a 70 MCA | AV18: Zurich - 0 a 100 MCA | AY18: Carretél | AZ18: Isoil | BA18: MV110 | BB18: ABZ003320 | CD18: Troca de conjunto feita pela chave seletora
A19: Amazonas (Reservatório) | B19: 127V | C19: Sem PLC | D19: Não tem | E19: Modem ABS | F19: Sem Redundância | G19: Clamper | J19: Conexel | K19: 7 - Reservatório | BZ19: Hidroestático
A20: Antonio de Castro | B20: 127V | C20: Altus Duo, 599014 | D20: Engetron | E20: Modem ABS | F20: Sem Redundância | G20: Lupa | J20: Weidmuller | K20: 10 - Vazão com VRP | U20: 7,5CV | V20: 220V | W20: 19,1A | X20: 3500 | Y20: 1.15 | AU20: 0 - 200 MCA | AV20: 0 - 200 MCA | AY20: Carretél | AZ20: Isoil | BA20: MV110 | BB20: ABW000673 | BH20: Carretél | BI20: Danfoss | BJ20: MAG 5000 | BK20: 083F5001 | CD20: 1 motor
A21: Ase-Grama | B21: 127V | C21: Altus Duo, 565574 | D21: Não tem | E21: Modem LUPA | F21: Fibra | G21: Lupa | H21: NH1 400A 690V | I21: Alphacomp CS Ethernet, Alphacomp RS 232 - RS 485, 2 Alphacomp 232-485 | J21: Weg | K21: 2 - Elevatória de Água | L21: 440V | M21: CFW110370T4SZ | N21: 1069895964 | O21: CFW110370T4SZ | P21: 1051050031 | U21: 250CV | V21: 440V | W21: 292A | X21: 1790 | Y21: 1.25 | Z21: Driver 1 | AA21: 250CV | AB21: 440V | AC21: 292A | AD21: 1790 | AE21: 1.25 | AF21: Driver 2 | AM21: BHS - WKL | AN21: 360 | AO21: 125 | AQ21: BHS - WKL | AR21: 360 | AS21: 125 | AU21: Zurich - 0 a 70 MCA | AV21: Conect - 0 a 200 MCA | AY21: Carretél | AZ21: Isoil | BA21: MV110 | BB21: ABV014420
A22: Assuene Ribeiro | B22: 127V | C22: Sem PLC | D22: Não tem | E22: Modem ABS | F22: Sem Redundância | G22: Clamper | J22: Conexel | K22: 11 - VRP/VMP | AU22: Zurick - 0 a 100 MCA | AV22: Zurick - 0 a 100 MCA | AY22: Carretél | AZ22: Isoil | BA22: MV110 | BB22: ABV007400
A23: Bairro de Lourdes (Reservatório) | B23: 127V | C23: Sem PLC | D23: Não tem | E23: Modem ABS | F23: Sem Redundância | G23: Lupa | J23: Conexel | K23: 7 - Reservatório | BZ23: Ultrassônico Nivelco - 0 a 5 m
A24: Bairu II | B24: 127V | C24: Altus Duo, 654988 | D24: APC | E24: Modem ABS | F24: Fibra | G24: Clamper | H24: NH2 630A 690V | I24: Alphacomp CS Ethernet | J24: Weg | K24: 2 - Elevatória de Água | L24: 440V | M24: CFW110312T4SZ | N24: 1068353167 | O24: CFW110312T4SZ | P24: 1068893017 | U24: 175CV | V24: 440V | W24: 209A | X24: 1791 | Y24: 1.25 | Z24: Driver 1 | AA24: 175CV | AB24: 440V | AC24: 209A | AD24: 1791 | AE24: 1.25 | AF24: Driver 2 | AM24: KSB MENT 250-200-500 GG | AN24: 400.8 | AO24: 90.4 | AQ24: KSB MENT 250-200-500 GG | AR24: 400.8 | AS24: 90.4 | AU24: Zurich - 0 a 70 MCA | AV24: Pressgage - 0 a 70 MCA | AY24: Carretél | AZ24: Isoil | BA24: MV110 | BB24: ABZ018176
A25: Barbosa Lage (Vazão) | B25: 127V | C25: Sem PLC | D25: Não tem | E25: Rádio | F25: Sem Redundância | I25: Alphacomp RS 232 - RS 485 | J25: Weg | K25: 9 - Vazão | AY25: Carretél | AZ25: Isoil | BA25: ML110 | CD25: Central de Rádio Não foi possível coletar o serial da Vazão
A26: Belmiro Braga | B26: 127V | C26: Altus Duo, SN 599028 | D26: Engetron | E26: Modem ABS Ethernet | F26: Fibra | G26: Lupa | H26: NH 2 710A 690V | I26: Alphacomp CS Ethernet, Alphacomp RS 232 - RS 485, Conversor de sinal 0-10V/4-20 mA | J26: Weg | K26: 2 - Elevatória de Água | L26: 440V | M26: CFW110211T4SZ | N26: 1023329962 | O26: CFW110370T4SZ | P26: 1051050031 | U26: 300CV | V26: 440 | W26: 343 | X26: 1790 | Y26: 1.15 | Z26: Driver 1 | AA26: 250CV | AB26: 440 | AC26: 292 | AD26: 1790 | AE26: 1.25 | AF26: Driver 2 | AM26: PP BSCA 200-450A EB | AN26: 880 | AU26: Zurich - 0 a 70 MCA | AV26: Zurich - 0 a 100 MCA | AY26: Carretél | AZ26: Indflow | BA26: BLIT-EM | BB26: 10000359
A27: Belo Vale (Booster) | B27: 127V | C27: WLP | D27: Não tem | E27: Modem ABS | F27: Sem Redundância | G27: Lupa | H27: D 16A 500V | K27: 1 - Booster | L27: 220V | M27: CFW110016T2SZ | N27: 1038965331 | U27: 3CV | V27: 220V | W27: 7.5A | X27: 3450 | Y27: 1.15 | Z27: Driver 1 | AA27: 3CV | AB27: 220V | AC27: 7.5A | AD27: 3450 | AE27: 1.15 | AF27: Driver 1 | AV27: SAR - 0 a 100 MCA | AW27: SAR - 0 a 100 MCA | CD27: Troca de conjunto feita pela chave seletora (ao lado do painel)
A28: Belo Vale (VRP) | B28: 127V | C28: Sem PLC | D28: Não tem | E28: Modem ABS | F28: Sem Redundância | G28: Lupa | J28: Weidmuller | K28: 10 - Vazão com VRP | AU28: Pressgage - Janela | AV28: SAR - 0 a 100 MCA | AY28: Carretél | AZ28: Isoil | BA28: MV110 | BB28: ABY013402 | BH28: Carretél | BI28: Indflow | BJ28: BLIT-EM | BK28: 10000354 | CD28: Vazão 1: Belo Vale Sensores: Pressgage Janela (0 a 30mca) Sar 0 a 100mca Vazão 2: Borda da Mata
A29: Benfica | B29: 127V | C29: WLP | D29: Não tem | E29: Modem ABS | F29: Sem Redundância | H29: NH00 40A 690V | J29: Weg | K29: 1 - Booster | L29: 220V | M29: CFW110024T2OFAZ | N29: 1041235936 | U29: 5CV | V29: 220V | W29: 12.8A | X29: 3475 | Y29: 1.15 | Z29: Driver 1 | AA29: 5CV | AB29: 220V | AC29: 12.8A | AD29: 3475 | AE29: 1.15 | AF29: Driver 1 | AU29: Pressgage - 0 a 100 MCA | AV29: Pressgage - 0 a 100 MCA
A30: Bethânia | B30: 127V | C30: WLP | D30: Não tem | E30: Modem ABS | F30: Sem Redundância | H30: NH00 40A 690V | J30: Balluff | K30: 1 - Booster | L30: 220V | M30: CFW110024TSOFAZ | N30: 1039443048 | U30: 5CV | V30: 220V | W30: 13.1 | X30: 3510 | Y30: 1.15 | Z30: Driver 1 | AA30: 5CV | AB30: 220V | AC30: 12.7 | AD30: 3505 | AE30: 1.15 | AF30: Driver 1 | AU30: Smar - 0 a 100 MCA | AV30: Conect - 0 a 100 MCA | CD30: Troca de conjunto feita pela chave seletora
A31: Boa vista/ Machado Sobrinho | B31: 127V | C31: Altus Duo, 601786 | D31: Engetron | E31: Modem ABS | F31: Fibra | G31: Lupa | H31: 3NE4 160A | I31: Alphacomp CS Ethernet, Alphacomp RS 232 - RS 485 | J31: Weg | K31: 8 - Reservatório com elevatória | L31: 220V | M31: CFW110070T2SZ | N31: 1024921062 | U31: 25CV | V31: 220V | W31: 63.8A | X31: 1770 | Y31: 1.25 | Z31: Driver 1 | AA31: 25CV | AB31: 220V | AC31: 63.8A | AD31: 1770 | AE31: 1.25 | AF31: Driver 1 | AM31: KSB MULTITEC C 65/4- 61 | AN31: 58 | AO31: 70 | AQ31: KSB MULTITEC C 65/4- 61 | AR31: 58 | AS31: 70 | AV31: Zurich - 0 a 100 MCA | AZ31: Indflow | BA31: BLIT-EM | BB31: 10000362 | BI31: Isoil | BJ31: BLIT-EM | BK31: 10000313 | BR31: Indflow | BS31: BLIT-EM | BT31: 10000370 | BZ31: Ultrassônico Nivelco - 0 a 5 m | CD31: Vazão Santa Luzia: Ultrassônico. M12180196
A32: Bom Clima | B32: 127V | C32: WLP | D32: Não tem | E32: Modem ABS | F32: Sem Redundância | H32: Simens 40A 500V | J32: Weg | K32: 1 - Booster | L32: 220V | M32: CFW110033T2OFAZ | N32: 1038510830 | U32: 10CV | V32: 220V | W32: 25.4A | X32: 1765 | Y32: 1.25 | Z32: Driver 1 | AA32: 10CV | AB32: 220V | AC32: 25.4A | AD32: 1765 | AE32: 1.25 | AF32: Driver 1 | AM32: MULTITEC C 50/6-41 | AN32: 15 | AO32: 80 | AQ32: MULTITEC C 50/60-41 | AR32: 15 | AS32: 40 | AU32: SAR - 0 a 100 MCA | AV32: SAR - 0 a 100 MCA | AY32: Carretél | AZ32: Isoil | BA32: MV110 | BB32: ABW000667 | CD32: Troca de conjunto feita pela chave seletora
A33: Bom Pastor | B33: 127V | C33: WLP | D33: Não tem | E33: Modem LUPA | F33: Sem Redundância | G33: WEG | H33: NH00 100A 690V | K33: 2 - Elevatória de Água | L33: 220V | M33: CFW110070T2OFAZ | N33: 1041228764 | U33: 25CV | V33: 220 | W33: 64.7 | X33: 1760 | Y33: 1.15 | Z33: Driver 1 | AA33: 25CV | AB33: 220 | AC33: 64.7 | AD33: 1760 | AE33: 1.15 | AF33: Driver 1 | AM33: KSB MULTITEC C 65/5 61 | AN33: 46.8 | AO33: 85 | AQ33: KSB MULTITEC C 65/5 61 | AR33: 46.8 | AS33: 85 | AV33: Pressgage - 0 a 100 MCA | AY33: Carretél | AZ33: Isoil | BA33: MV110 | BB33: ABZ003316
A34: Bonsucesso (Reservatório) | B34: 127V | C34: Sem PLC | D34: Engetron | E34: Modem ABS | F34: Sem Redundância | G34: Lupa | J34: LR Informática | K34: 7 - Reservatório | BZ34: Radar Nivelco
A35: Bonsucesso/ Parque ABC | B35: 127V | C35: Altus Duo, 601790 | D35: Não tem | E35: Modem LUPA | F35: Sem Redundância | G35: Lupa | H35: NH00 160A 690V | J35: Weg | K35: 8 - Reservatório com elevatória | L35: 220V | M35: CFW110105T2OFAZ | N35: 1042514038 | U35: 30CV | V35: 220V | W35: 71.8A | X35: 3555 | Y35: 1.25 | Z35: Driver 1 | AA35: 30CV | AB35: 220V | AC35: 71.8 | AD35: 3555 | AE35: 1.25 | AF35: Driver 1 | AM35: KSB METB 80-50-200 GG | AN35: 77.98 | AO35: 79.96 | AQ35: KSB METB 80-50-200 GG | AR35: 77.98 | AS35: 79.96 | AV35: Zurich - 0 a 100 MCA | BZ35: Ultrassônico Nivelco - 0 a 5 m
A36: Borboleta | B36: 127V | C36: Sem PLC | D36: Não tem | E36: Modem ABS | F36: Sem Redundância | G36: Lupa | J36: Weidmuller | K36: 10 - Vazão com VRP | AU36: Zurick - 0 a 100 MCA | AV36: Zurick - 0 a 70 MCA | AY36: Carretél | AZ36: Isoil | BA36: MV110 | BB36: ABV007422
A37: Bosque do Imperador | B37: 127V | C37: WLP | D37: Não tem | E37: Modem LUPA | F37: Sem Redundância | G37: Clamper | H37: NH1 160A 690V | I37: Conversor 232/485 | J37: Conexel | K37: 2 - Elevatória de Água | L37: 220V | M37: CFW110045T2SZ | N37: 1006490973 | U37: 15CV | V37: 220V | W37: 36.2A | X37: 3520 | Y37: 1.15 | Z37: Driver 1 | AA37: 15CV | AB37: 220V | AC37: 36.2A | AD37: 3520 | AE37: 1.15 | AF37: Driver 1 | AU37: Zurich - 0 a 100 MCA | AV37: Zurich - 0 a 200 MCA | AY37: Carretél | AZ37: Isoil | BA37: MV110 | BB37: ABZ003341
A38: Boto 1 | B38: 127V | C38: Altus Duo, 601799 | D38: Não tem | E38: Modem LUPA | F38: Sem Redundância | G38: Lupa | H38: NH00 160A 690V | J38: Weidmuller | K38: 2 - Elevatória de Água | L38: 220V | M38: CFW110105T2OFAZ | N38: 1041335797 | U38: 20CV | V38: 220V | W38: 47A | X38: 3510 | Y38: 1.15 | Z38: Driver 1 | AA38: 20CV | AB38: 220V | AC38: 47A | AD38: 3510 | AE38: 1.15 | AF38: Driver 1 | AU38: Pressgage - 0 a 70 MCA | AV38: SMAR - Janela | AZ38: Isoil | BA38: BLIT-EM | BB38: 10000371 | CD38: Recalque: Smar -14.7 - 360 psi Troca de Conjunto feita pela chave seletora
A39: Boto 2/Boto 1 | B39: 127V | C39: WLP | D39: Não tem | E39: Modem ABS | F39: Sem Redundância | H39: NH00 40A 690V | K39: 8 - Reservatório com elevatória | L39: 220V | M39: CFW110028T2OFAZ | N39: 1053513482 | U39: 4CV | V39: 220V | W39: 10.7A | X39: 3450 | Y39: 1.15 | Z39: Driver 1 | AA39: 4CV | AB39: 220V | AC39: 10.7A | AD39: 3450 | AE39: 1.15 | AF39: Driver 1 | AU39: Zurich - 0 a 70 MCA | AV39: Zurich - 0 a 70 MCA | BZ39: Pressão | CD39: Troca de conjunto feita pela chave seletora
A40: Caiçaras (Elevatória) | B40: 127V | C40: Sem PLC | D40: Não tem | E40: Modem ABS | F40: Sem Redundância | H40: NH00 160A 690V | I40: Conversor de sinal 0-10V/4-20 mA | J40: Conexel | K40: 2 - Elevatória de Água | L40: 220V | M40: CFW110070T2OFAZ | N40: 1024479121 | U40: 20CV | V40: 220V | W40: 53.3A | X40: 1765 | Y40: 1.15 | Z40: Driver 1 | AA40: 20CV | AB40: 220V | AC40: 53.3A | AD40: 1765 | AE40: 1.15 | AF40: Driver 1 | AM40: Flowserve | AQ40: Flowserve | AU40: Zurich - 0 a 100 MCA | AV40: Pressgage - 0 a 100 MCA
...

Sheet BR 440 (VRP)
B1: Dados dos Equipamentos Local: BR 440 Tipo: VRP
A5: Dados Telemetria
A6: Comunicação | B6: ='Respostas ao formulário 1'!E236 -> Modem ABS
A7: Redundância | B7: ='Respostas ao formulário 1'!F236 -> 0
A8: Alimentação | B8: ='Respostas ao formulário 1'!J236 -> Weg
A9: DPS | B9: ='Respostas ao formulário 1'!G236 -> Clamper
A11: Dados da VRP
A12: Sensor à Jusante | B12: ='Respostas ao formulário 1'!AU236 -> 0 a 70 MCA
A13: Sensor à Montante | B13: ='Respostas ao formulário 1'!AV236 -> 0 a 100 MCA
A14: Modelo Vazão | B14: ='Respostas ao formulário 1'!BA236 -> 0

Sheet Caiçaras Novo
B1: Dados dos Equipamentos Local: Caiçaras Novo Tipo: Reservatório
A5: Dados Telemetria
A6: Comunicação | B6: ='Respostas ao formulário 1'!E235 -> Rádio
A7: Redundância | B7: ='Respostas ao formulário 1'!F235 -> Sem Redundância
A8: Alimentação | B8: ='Respostas ao formulário 1'!J235 -> 0
A9: DPS | B9: ='Respostas ao formulário 1'!G235 -> 0
A11: Dados do Reservatório
A12: Tipo de Sensor | B12: ='Respostas ao formulário 1'!BZ235 -> Radar Nivelco
A13: Fusível | B13: ='Respostas ao formulário 1'!H235 -> 0
A15: Dimensões
A16: Altura Total (m)
A18: Altura do 0% (4mA) (m)
A20: Altura do 100% (20mA) (m)

Sheet Cesário Alvim
B1: Dados dos Equipamentos Local: Cesário Alvim Tipo: Elevatória de Água
A5: Dados Telemetria
A6: Comunicação | B6: ='Respostas ao formulário 1'!E54 -> Modem ABS
A7: Redundância | B7: ='Respostas ao formulário 1'!F54 -> Sem Redundância
A8: Marca da Fonte | B8: ='Respostas ao formulário 1'!J54 -> 0
A9: DPS | B9: ='Respostas ao formulário 1'!G54 -> 0
A11: Dados Inversor
A12: Acionamento | B12: ='Respostas ao formulário 1'!L54 -> 220V
A13: Fusível | B13: ='Respostas ao formulário 1'!H54 -> NH2 315A 690V
A14: Driver 1 | B14: ='Respostas ao formulário 1'!M54 -> CFW110180T2SZ
A15: Serial | B15: ='Respostas ao formulário 1'!N54 -> 1051102596
A17: Dados Motores
A18: Fabricante | B18: Carcaça | C18: Potência | D18: Tensão | E18: Corrente | F18: RPM | G18: FS | H18: Acionamento
C19: ='Respostas ao formulário 1'!U54 -> 50CV | D19: ='Respostas ao formulário 1'!V54 -> 220V | E19: ='Respostas ao formulário 1'!W54 -> 121A | F19: ='Respostas ao formulário 1'!X54 -> 3570 | G19: ='Respostas ao formulário 1'!Y54 -> 1.25 | H19: ='Respostas ao formulário 1'!Z54 -> Driver 1
A20: Fabricante | B20: Carcaça | C20: Potência | D20: Tensão | E20: Corrente | F20: RPM | G20: FS | H20: Acionamento
C21: ='Respostas ao formulário 1'!AA54 -> 50CV | D21: ='Respostas ao formulário 1'!AB54 -> 220V | E21: ='Respostas ao formulário 1'!AC54 -> 121A | F21: ='Respostas ao formulário 1'!AD54 -> 3570 | G21: ='Respostas ao formulário 1'!AE54 -> 1.25 | H21: ='Respostas ao formulário 1'!AF54 -> Driver 1
A23: Sensores
A24: Sucção | B24: Recalque | C24: Modelo Vazão
A25: ='Respostas ao formulário 1'!AU54 -> Zurich - 0 a 70 MCA | B25: ='Respostas ao formulário 1'!AV54 -> Zurich - 0 a 200 MCA | C25: ='Respostas ao formulário 1'!BA54 -> MV110

Sheet Santa Isabel
B1: Dados dos Equipamentos Local: Santa Isabel Tipo: Booster
A5: Dados Telemetria
A6: Comunicação | B6: ='Respostas ao formulário 1'!E185 -> Modem ABS
A7: Redundância | B7: ='Respostas ao formulário 1'!F185 -> Sem Redundância
A8: Marca da Fonte | B8: ='Respostas ao formulário 1'!J185 -> Delta
A9: DPS | B9: ='Respostas ao formulário 1'!G185 -> 0
A11: Dados Inversor
A12: Acionamento | B12: ='Respostas ao formulário 1'!L185 -> 220V
A13: Fusível | B13: ='Respostas ao formulário 1'!H185 -> NH00 50A 500V
A14: Driver 1 | B14: ='Respostas ao formulário 1'!M185 -> CFW110045T2SZ
A15: Serial | B15: ='Respostas ao formulário 1'!N185 -> 1066032030
A17: Dados Motores
A18: Fabricante | B18: Carcaça | C18: Potência | D18: Tensão | E18: Corrente | F18: RPM | G18: FS | H18: Acionamento
C19: ='Respostas ao formulário 1'!U185 -> 15CV | D19: ='Respostas ao formulário 1'!V185 -> 220V | E19: ='Respostas ao formulário 1'!W185 -> 35.4A | F19: ='Respostas ao formulário 1'!X185 -> 3510 | G19: ='Respostas ao formulário 1'!Y185 -> 1.15 | H19: ='Respostas ao formulário 1'!Z185 -> Driver 1
A20: Fabricante | B20: Carcaça | C20: Potência | D20: Tensão | E20: Corrente | F20: RPM | G20: FS | H20: Acionamento
C21: ='Respostas ao formulário 1'!AA185 -> 15CV | D21: ='Respostas ao formulário 1'!AB185 -> 220V | E21: ='Respostas ao formulário 1'!AC185 -> 35.4A | F21: ='Respostas ao formulário 1'!AD185 -> 3510 | G21: ='Respostas ao formulário 1'!AE185 -> 1.15 | H21: ='Respostas ao formulário 1'!AF185 -> Driver 1
A23: Sensores
A24: Sucção | B24: Recalque | C24: Modelo Vazão
A25: ='Respostas ao formulário 1'!AU185 -> Zurich - 0 a 70 MCA | B25: ='Respostas ao formulário 1'!AV185 -> Zurich - 0 a 200 MCA | C25: ='Respostas ao formulário 1'!BA185 -> 0

Sheet São Damião
B1: Dados dos Equipamentos Local: São Damião Tipo: Booster
A5: Dados Telemetria
A6: Comunicação | B6: ='Respostas ao formulário 1'!E198 -> Modem ABS
A7: Redundância | B7: ='Respostas ao formulário 1'!F198 -> Sem Redundância
A8: Marca da Fonte | B8: ='Respostas ao formulário 1'!J198 -> LR Informática
A9: DPS | B9: ='Respostas ao formulário 1'!G198 -> 0
A11: Dados Inversor
A12: Acionamento | B12: ='Respostas ao formulário 1'!L198 -> 220V
A13: Fusível | B13: ='Respostas ao formulário 1'!H198 -> NH1 350A 690V
A14: Driver 1 | B14: ='Respostas ao formulário 1'!M198 -> CFW110180T2SZ
A15: Serial | B15: ='Respostas ao formulário 1'!N198 -> 1053340198
A17: Dados Motores
A18: Fabricante | B18: Carcaça | C18: Potência | D18: Tensão | E18: Corrente | F18: RPM | G18: FS | H18: Acionamento
C19: ='Respostas ao formulário 1'!U198 -> 40CV | D19: ='Respostas ao formulário 1'!V198 -> 220V | E19: ='Respostas ao formulário 1'!W198 -> 99A | F19: ='Respostas ao formulário 1'!X198 -> 3560 | G19: ='Respostas ao formulário 1'!Y198 -> 1.25 | H19: ='Respostas ao formulário 1'!Z198 -> Driver 1
A20: Fabricante | B20: Carcaça | C20: Potência | D20: Tensão | E20: Corrente | F20: RPM | G20: FS | H20: Acionamento
C21: ='Respostas ao formulário 1'!AA198 -> 40CV | D21: ='Respostas ao formulário 1'!AB198 -> 220V | E21: ='Respostas ao formulário 1'!AC198 -> 99A | F21: ='Respostas ao formulário 1'!AD198 -> 3560 | G21: ='Respostas ao formulário 1'!AE198 -> 1.25 | H21: ='Respostas ao formulário 1'!AF198 -> Driver 1
A23: Sensores
A24: Sucção | B24: Recalque | C24: Modelo Vazão
A25: ='Respostas ao formulário 1'!AU198 -> Pressgage - 0 a 100 MCA | B25: ='Respostas ao formulário 1'!AV198 -> Zurich - 0 a 200 MCA | C25: ='Respostas ao formulário 1'!BA198 -> MV110

Sheet São Judas 1
B1: Dados dos Equipamentos Local:São Judas 1 Tipo: Elevatória de Água
A5: Dados Telemetria | C5: *Aqui é importante manter o conjunto 2 em funcionamento porque ele tem uma vazão maior do que a do conjunto 1
A6: Comunicação | B6: ='Respostas ao formulário 1'!E200 -> Modem ABS
A7: Redundância | B7: ='Respostas ao formulário 1'!F200 -> Sem Redundância
A8: Marca da Fonte | B8: ='Respostas ao formulário 1'!J200 -> Weg
A9: DPS | B9: ='Respostas ao formulário 1'!G200 -> Clamper
A11: Dados Inversor
A12: Acionamento | B12: ='Respostas ao formulário 1'!L200 -> 220V
A13: Fusível | B13: ='Respostas ao formulário 1'!H200 -> NH00 160A 690V
A14: Driver 1 | B14: ='Respostas ao formulário 1'!M200 -> CFW110105T2SZ
A15: Serial | B15: ='Respostas ao formulário 1'!N200 -> 1067714486
A17: Dados Motores
A18: Fabricante | B18: Carcaça | C18: Potência | D18: Tensão | E18: Corrente | F18: RPM | G18: FS | H18: Acionamento
C19: ='Respostas ao formulário 1'!U200 -> 40CV | D19: ='Respostas ao formulário 1'!V200 -> 220V | E19: ='Respostas ao formulário 1'!W200 -> 102A | F19: ='Respostas ao formulário 1'!X200 -> 1780 | G19: ='Respostas ao formulário 1'!Y200 -> 1.25 | H19: ='Respostas ao formulário 1'!Z200 -> Driver 1
A20: Fabricante | B20: Carcaça | C20: Potência | D20: Tensão | E20: Corrente | F20: RPM | G20: FS | H20: Acionamento
C21: ='Respostas ao formulário 1'!AA200 -> 40CV | D21: ='Respostas ao formulário 1'!AB200 -> 220V | E21: ='Respostas ao formulário 1'!AC200 -> 102A | F21: ='Respostas ao formulário 1'!AD200 -> 1780 | G21: ='Respostas ao formulário 1'!AE200 -> 1.25 | H21: ='Respostas ao formulário 1'!AF200 -> Driver 1
A23: Sensores
A24: Sucção | B24: Recalque | C24: Vazão
A25: ='Respostas ao formulário 1'!AU200 -> Zurich - 0 a 70 MCA | B25: ='Respostas ao formulário 1'!AV200 -> Pressgage - 0 a 100 MCA | C25: ='Respostas ao formulário 1'!BA200 -> MV110

Sheet Spinaville
B1: Dados dos Equipamentos Local:Spinaville Tipo: Elevatória de Água
A5: Dados Telemetria
A6: Comunicação | B6: ='Respostas ao formulário 1'!E208 -> Modem ABS
A7: Redundância | B7: ='Respostas ao formulário 1'!F208 -> Sem Redundância
A8: Marca da Fonte | B8: ='Respostas ao formulário 1'!J208 -> Weidmuller
A9: DPS | B9: ='Respostas ao formulário 1'!G208 -> 0
A11: Dados Inversor
A12: Acionamento | B12: ='Respostas ao formulário 1'!L208 -> 220V
A13: Fusível | B13: ='Respostas ao formulário 1'!H208 -> NH00 60A 690V
A14: Driver 1 | B14: ='Respostas ao formulário 1'!M208 -> CFW110054T2OFAZ
A15: Serial | B15: ='Respostas ao formulário 1'!N208 -> 1039442997
A17: Dados Motores
A18: Fabricante | B18: Carcaça | C18: Potência | D18: Tensão | E18: Corrente | F18: RPM | G18: FS | H18: Acionamento
C19: ='Respostas ao formulário 1'!U208 -> 20CV | D19: ='Respostas ao formulário 1'!V208 -> 220V | E19: ='Respostas ao formulário 1'!W208 -> 49.8A | F19: ='Respostas ao formulário 1'!X208 -> 3545 | G19: ='Respostas ao formulário 1'!Y208 -> 1.25 | H19: ='Respostas ao formulário 1'!Z208 -> Driver 1
A21: Sensores
A22: Sucção | B22: Recalque | C22: Vazão
A23: ='Respostas ao formulário 1'!AU208 -> Zurich - 0 a 70 MCA | B23: ='Respostas ao formulário 1'!AV208 -> Zurich - 0 a 200 MCA | C23: ='Respostas ao formulário 1'!BA208 -> MV110

Sheet Santa Casa
B1: Dados dos Equipamentos Local: Santa Casa Tipo: Vazão
A5: Dados Telemetria
A6: Comunicação | B6: ='Respostas ao formulário 1'!E182 -> Modem LUPA
A7: Redundância | B7: ='Respostas ao formulário 1'!F182 -> Sem Redundância
A8: Alimentação | B8: ='Respostas ao formulário 1'!J182 -> LR Informática
A9: PLC | B9: ='Respostas ao formulário 1'!C182 -> Altus 104
A10: DPS | B10: ='Respostas ao formulário 1'!G182 -> Lupa
A12: Dados da Estação
A13: Sensor | B13: ='Respostas ao formulário 1'!AU182 -> 0
A14: Modelo Vazão | B14: ='Respostas ao formulário 1'!BA182 -> Mag 5000

Sheet Pq Independencia 1 Pq Independe
B1: Dados dos Equipamentos Local: Parque Independência 2/ Parque Independência 1 Tipo: Reservatório com Elevatória
A5: Dados Telemetria
A6: Comunicação | B6: ='Respostas ao formulário 1'!E154 -> Modem ABS
A7: Redundância | B7: ='Respostas ao formulário 1'!F154 -> Sem Redundância
A8: Marca da Fonte | B8: ='Respostas ao formulário 1'!J154 -> Conexel Power
A9: DPS | B9: ='Respostas ao formulário 1'!G154 -> 0
A11: Dados Inversor
A12: Acionamento | B12: ='Respostas ao formulário 1'!L154 -> 220V
A13: Fusível | B13: ='Respostas ao formulário 1'!H154 -> 0
A14: Driver 1 | B14: ='Respostas ao formulário 1'!M154 -> CFW110007T2OFAZ
A15: Serial | B15: ='Respostas ao formulário 1'!N154 -> 1051643054
A17: Dados Motores
A18: Fabricante | B18: Carcaça | C18: Potência | D18: Tensão | E18: Corrente | F18: RPM | G18: FS | H18: Acionamento
C19: ='Respostas ao formulário 1'!U154 -> 1.5CV | D19: ='Respostas ao formulário 1'!V154 -> 220V | E19: ='Respostas ao formulário 1'!W154 -> 4.4A | F19: ='Respostas ao formulário 1'!X154 -> 3420 | G19: ='Respostas ao formulário 1'!Y154 -> 1.15 | H19: ='Respostas ao formulário 1'!Z154 -> Driver 1
A20: Fabricante | B20: Carcaça | C20: Potência | D20: Tensão | E20: Corrente | F20: RPM | G20: FS | H20: Acionamento
C21: ='Respostas ao formulário 1'!AA154 -> 1.5CV | D21: ='Respostas ao formulário 1'!AB154 -> 220V | E21: ='Respostas ao formulário 1'!AC154 -> 4.4A | F21: ='Respostas ao formulário 1'!AD154 -> 3420 | G21: ='Respostas ao formulário 1'!AE154 -> 1.15 | H21: ='Respostas ao formulário 1'!AF154 -> Driver 1
A23: Sensores
A24: Sucção | B24: Recalque | C24: Modelo Vazão
A25: ='Respostas ao formulário 1'!AU154 -> 0 | B25: ='Respostas ao formulário 1'!AV154 -> Zurich - 0 a 100 MCA | C25: ='Respostas ao formulário 1'!BA154 -> MV110
A27: Dados do Reservatório
A28: Tipo de Sensor | B28: ='Respostas ao formulário 1'!BZ154 -> Ultrassônico Nivelco - 0 a 5 m
A30: Dimensões
A31: Altura Total (m)
A32: 3.5
A33: Altura do 0% (4mA) (m)
A34: 0
A35: Altura do 100% (20mA) (m)
A36: 3.05

Sheet Nova Benfica 3Nova Benfica 2
B1: Dados dos Equipamentos Local: Nova Benfica 3/ Nova Benfica 2 Tipo: Reservatório com Elevatória
A5: Dados Telemetria
A6: Comunicação | B6: ='Respostas ao formulário 1'!E136 -> Modem ABS
A7: Redundância | B7: ='Respostas ao formulário 1'!F136 -> Sem Redundância
A8: Marca da Fonte | B8: ='Respostas ao formulário 1'!J120 -> Conexel
A9: DPS | B9: ='Respostas ao formulário 1'!G120 -> 0
A11: Dados Inversor
A12: Acionamento | B12: ='Respostas ao formulário 1'!L136 -> 200V
A13: Fusível | B13: ='Respostas ao formulário 1'!H136 -> 0
A14: Driver 1 | B14: ='Respostas ao formulário 1'!M136 -> CFW110007T2OFAZ
A15: Serial | B15: ='Respostas ao formulário 1'!N136 -> 1067389201
A17: Dados Motores
A18: Fabricante | B18: Carcaça | C18: Potência | D18: Tensão | E18: Corrente | F18: RPM | G18: FS | H18: Acionamento
C19: ='Respostas ao formulário 1'!U136 -> 0.5 CV | D19: ='Respostas ao formulário 1'!V136 -> 220V | E19: ='Respostas ao formulário 1'!W136 -> 2A | F19: ='Respostas ao formulário 1'!X136 -> 3485 | G19: ='Respostas ao formulário 1'!Y136 -> 1.60 | H19: ='Respostas ao formulário 1'!Z136 -> Driver 1
A20: Fabricante | B20: Carcaça | C20: Potência | D20: Tensão | E20: Corrente | F20: RPM | G20: FS | H20: Acionamento
C21: ='Respostas ao formulário 1'!AA136 -> 0.5CV | D21: ='Respostas ao formulário 1'!AB136 -> 220V | E21: ='Respostas ao formulário 1'!AC136 -> 2A | F21: ='Respostas ao formulário 1'!AD136 -> 3485 | G21: ='Respostas ao formulário 1'!AE136 -> 1.60 | H21: ='Respostas ao formulário 1'!AF136 -> Driver 1
A23: Sensores
A24: Sucção | B24: Recalque | C24: Modelo Vazão
A25: ='Respostas ao formulário 1'!AU136 -> 0 | B25: ='Respostas ao formulário 1'!AV136 -> SAR - Janela | C25: ='Respostas ao formulário 1'!BA136 -> 0
A27: Dados do Reservatório
A28: Tipo de Sensor | B28: ='Respostas ao formulário 1'!BZ136 -> Ultrassônico Nivelco - 0 a 5 m
A30: Dimensões
A31: Altura Total (m)
A32: 4.03
A33: Altura do 0% (4mA) (m)
A34: 0
A35: Altura do 100% (20mA) (m)
A36: 3.2

Sheet Bosque do Imperador
B1: Dados dos Equipamentos Local: Bosque do Imperador Tipo: Elevatória de Água
A5: Dados Telemetria
A6: Comunicação | B6: ='Respostas ao formulário 1'!E37 -> Modem LUPA
A7: Redundância | B7: ='Respostas ao formulário 1'!F37 -> Sem Redundância
A8: Marca da Fonte | B8: ='Respostas ao formulário 1'!J37 -> Conexel
A9: DPS | B9: ='Respostas ao formulário 1'!G37 -> Clamper
A11: Dados Inversor
A12: Acionamento | B12: ='Respostas ao formulário 1'!L37 -> 220V
A13: Fusível | B13: ='Respostas ao formulário 1'!H37 -> NH1 160A 690V
A14: Driver 1 | B14: ='Respostas ao formulário 1'!M37 -> CFW110045T2SZ
A15: Serial | B15: ='Respostas ao formulário 1'!N37 -> 1006490973
A17: Dados Motores
A18: Fabricante | B18: Carcaça | C18: Potência | D18: Tensão | E18: Corrente | F18: RPM | G18: FS | H18: Acionamento
C19: ='Respostas ao formulário 1'!U37 -> 15CV | D19: ='Respostas ao formulário 1'!V37 -> 220V | E19: ='Respostas ao formulário 1'!W37 -> 36.2A | F19: ='Respostas ao formulário 1'!X37 -> 3520 | G19: ='Respostas ao formulário 1'!Y37 -> 1.15 | H19: ='Respostas ao formulário 1'!Z37 -> Driver 1
A20: Fabricante | B20: Carcaça | C20: Potência | D20: Tensão | E20: Corrente | F20: RPM | G20: FS | H20: Acionamento
C21: ='Respostas ao formulário 1'!AA37 -> 15CV | D21: ='Respostas ao formulário 1'!AB37 -> 220V | E21: ='Respostas ao formulário 1'!AC37 -> 36.2A | F21: ='Respostas ao formulário 1'!AD37 -> 3520 | G21: ='Respostas ao formulário 1'!AE37 -> 1.15 | H21: ='Respostas ao formulário 1'!AF37 -> Driver 1
A23: Sensores
A24: Sucção | B24: Recalque | C24: Modelo Vazão
A25: ='Respostas ao formulário 1'!AU37 -> Zurich - 0 a 100 MCA | B25: ='Respostas ao formulário 1'!AV37 -> Zurich - 0 a 200 MCA | C25: ='Respostas ao formulário 1'!BA37 -> MV110

Sheet Borboleta
B1: Dados dos Equipamentos Local: Borboleta Tipo: VRP
A5: Dados Telemetria
A6: Comunicação | B6: ='Respostas ao formulário 1'!E36 -> Modem ABS
A7: Redundância | B7: ='Respostas ao formulário 1'!F36 -> Sem Redundância
A8: Alimentação | B8: ='Respostas ao formulário 1'!J36 -> Weidmuller
A9: DPS | B9: ='Respostas ao formulário 1'!G36 -> Lupa
A11: Dados da VRP
A12: Sensor à Jusante | B12: ='Respostas ao formulário 1'!AU36 -> Zurick - 0 a 100 MCA
A13: Sensor à Montante | B13: ='Respostas ao formulário 1'!AV36 -> Zurick - 0 a 70 MCA
A14: Modelo Vazão 1 | B14: ='Respostas ao formulário 1'!BA36 -> MV110

Sheet Bethania
B1: Dados dos Equipamentos Local: Bethânia Tipo: Booster
A5: Dados Telemetria
A6: Comunicação | B6: ='Respostas ao formulário 1'!E30 -> Modem ABS
A7: Redundância | B7: ='Respostas ao formulário 1'!F30 -> Sem Redundância
A8: Marca da Fonte | B8: ='Respostas ao formulário 1'!J30 -> Balluff
A9: DPS | B9: ='Respostas ao formulário 1'!G30 -> 0
A11: Dados Inversor
A12: Acionamento | B12: ='Respostas ao formulário 1'!L30 -> 220V
A13: Fusível | B13: ='Respostas ao formulário 1'!H30 -> NH00 40A 690V
A14: Driver 1 | B14: ='Respostas ao formulário 1'!M30 -> CFW110024TSOFAZ
A15: Serial | B15: ='Respostas ao formulário 1'!N30 -> 1039443048
A17: Dados Motores
A18: Fabricante | B18: Carcaça | C18: Potência | D18: Tensão | E18: Corrente | F18: RPM | G18: FS | H18: Acionamento
C19: ='Respostas ao formulário 1'!U30 -> 5CV | D19: ='Respostas ao formulário 1'!V30 -> 220V | E19: ='Respostas ao formulário 1'!W30 -> 13.1 | F19: ='Respostas ao formulário 1'!X30 -> 3510 | G19: ='Respostas ao formulário 1'!Y30 -> 1.15 | H19: ='Respostas ao formulário 1'!Z30 -> Driver 1
A20: Fabricante | B20: Carcaça | C20: Potência | D20: Tensão | E20: Corrente | F20: RPM | G20: FS | H20: Acionamento
C21: ='Respostas ao formulário 1'!AA30 -> 5CV | D21: ='Respostas ao formulário 1'!AB30 -> 220V | E21: ='Respostas ao formulário 1'!AC30 -> 12.7 | F21: ='Respostas ao formulário 1'!AD30 -> 3505 | G21: ='Respostas ao formulário 1'!AE30 -> 1.15 | H21: ='Respostas ao formulário 1'!AF30 -> Driver 1
A23: Sensores
A24: Sucção | B24: Recalque | C24: Modelo Vazão
A25: ='Respostas ao formulário 1'!AU30 -> Smar - 0 a 100 MCA | B25: ='Respostas ao formulário 1'!AV30 -> Conect - 0 a 100 MCA | C25: ='Respostas ao formulário 1'!BA30 -> 0

Sheet Benfica (Booster)
B1: Dados dos Equipamentos Local: Benfica Tipo: Booster
A5: Dados Telemetria
A6: Comunicação | B6: ='Respostas ao formulário 1'!E29 -> Modem ABS
A7: Redundância | B7: ='Respostas ao formulário 1'!F29 -> Sem Redundância
A8: Marca da Fonte | B8: ='Respostas ao formulário 1'!J29 -> Weg
A9: DPS | B9: ='Respostas ao formulário 1'!G29 -> 0
A11: Dados Inversor
A12: Acionamento | B12: ='Respostas ao formulário 1'!L29 -> 220V
A13: Fusível | B13: ='Respostas ao formulário 1'!H29 -> NH00 40A 690V
A14: Driver 1 | B14: ='Respostas ao formulário 1'!M29 -> CFW110024T2OFAZ
A15: Serial | B15: ='Respostas ao formulário 1'!N29 -> 1041235936
A17: Dados Motores
A18: Fabricante | B18: Carcaça | C18: Potência | D18: Tensão | E18: Corrente | F18: RPM | G18: FS | H18: Acionamento
C19: ='Respostas ao formulário 1'!U29 -> 5CV | D19: ='Respostas ao formulário 1'!V29 -> 220V | E19: ='Respostas ao formulário 1'!W29 -> 12.8A | F19: ='Respostas ao formulário 1'!X29 -> 3475 | G19: ='Respostas ao formulário 1'!Y29 -> 1.15 | H19: ='Respostas ao formulário 1'!Z29 -> Driver 1
A20: Fabricante | B20: Carcaça | C20: Potência | D20: Tensão | E20: Corrente | F20: RPM | G20: FS | H20: Acionamento
C21: ='Respostas ao formulário 1'!AA29 -> 5CV | D21: ='Respostas ao formulário 1'!AB29 -> 220V | E21: ='Respostas ao formulário 1'!AC29 -> 12.8A | F21: ='Respostas ao formulário 1'!AD29 -> 3475 | G21: ='Respostas ao formulário 1'!AE29 -> 1.15 | H21: ='Respostas ao formulário 1'!AF29 -> Driver 1
A23: Sensores
A24: Sucção | B24: Recalque | C24: Modelo Vazão
A25: ='Respostas ao formulário 1'!AU29 -> Pressgage - 0 a 100 MCA | B25: ='Respostas ao formulário 1'!AV29 -> Pressgage - 0 a 100 MCA | C25: ='Respostas ao formulário 1'!BA29 -> 0

Sheet Belo Vale (VRP)
B1: Dados dos Equipamentos Local: Belo Vale/ Borda da Mata Tipo: VRP
A5: Dados Telemetria
A6: Comunicação | B6: ='Respostas ao formulário 1'!E27 -> Modem ABS
A7: Redundância | B7: ='Respostas ao formulário 1'!F27 -> Sem Redundância
A8: Alimentação | B8: ='Respostas ao formulário 1'!J27 -> 0
A9: DPS | B9: ='Respostas ao formulário 1'!G27 -> Lupa
A11: Dados da VRP
A12: Sensor à Jusante | B12: ='Respostas ao formulário 1'!AU27 -> 0
A13: Sensor à Montante | B13: ='Respostas ao formulário 1'!AV27 -> SAR - 0 a 100 MCA
A14: Modelo Vazão Belo Vale | B14: ='Respostas ao formulário 1'!BA27 -> 0
A15: Modelo Vazão Borda da Mata | B15: ='Respostas ao formulário 1'!BJ27 -> 0

Sheet Belo Vale
B1: Dados dos Equipamentos Local: Belo Vale Tipo: Booster
A5: Dados Telemetria
A6: Comunicação | B6: ='Respostas ao formulário 1'!E27 -> Modem ABS
A7: Redundância | B7: ='Respostas ao formulário 1'!F27 -> Sem Redundância
A8: Marca da Fonte | B8: ='Respostas ao formulário 1'!J27 -> 0
A9: DPS | B9: ='Respostas ao formulário 1'!G27 -> Lupa
A11: Dados Inversor
A12: Acionamento | B12: ='Respostas ao formulário 1'!L27 -> 220V
A13: Fusível | B13: ='Respostas ao formulário 1'!H27 -> D 16A 500V
A14: Driver 1 | B14: ='Respostas ao formulário 1'!M27 -> CFW110016T2SZ
A15: Serial | B15: ='Respostas ao formulário 1'!N27 -> 1038965331
A17: Dados Motores
A18: Fabricante | B18: Carcaça | C18: Potência | D18: Tensão | E18: Corrente | F18: RPM | G18: FS | H18: Acionamento
C19: ='Respostas ao formulário 1'!U27 -> 3CV | D19: ='Respostas ao formulário 1'!V27 -> 220V | E19: ='Respostas ao formulário 1'!W27 -> 7.5A | F19: ='Respostas ao formulário 1'!X27 -> 3450 | G19: ='Respostas ao formulário 1'!Y27 -> 1.15 | H19: ='Respostas ao formulário 1'!Z27 -> Driver 1
A20: Fabricante | B20: Carcaça | C20: Potência | D20: Tensão | E20: Corrente | F20: RPM | G20: FS | H20: Acionamento
C21: ='Respostas ao formulário 1'!AA27 -> 3CV | D21: ='Respostas ao formulário 1'!AB27 -> 220V | E21: ='Respostas ao formulário 1'!AC27 -> 7.5A | F21: ='Respostas ao formulário 1'!AD27 -> 3450 | G21: ='Respostas ao formulário 1'!AE27 -> 1.15 | H21: ='Respostas ao formulário 1'!AF27 -> Driver 1
A23: Sensores
A24: Sucção | B24: Recalque | C24: Modelo Vazão
A25: ='Respostas ao formulário 1'!AU27 -> 0 | B25: ='Respostas ao formulário 1'!AV27 -> SAR - 0 a 100 MCA | C25: ='Respostas ao formulário 1'!BA27 -> 0

Sheet Belmiro Braga
B1: Dados dos Equipamentos Local: Belmiro Braga Tipo: Elevatória de Água
A5: Dados Telemetria
A6: Comunicação | B6: ='Respostas ao formulário 1'!E26 -> Modem ABS Ethernet
A7: Redundância | B7: ='Respostas ao formulário 1'!F26 -> Fibra
A8: Marca da Fonte | B8: ='Respostas ao formulário 1'!J26 -> Weg
A9: DPS | B9: ='Respostas ao formulário 1'!G26 -> Lupa
A11: Dados Inversor
A12: Acionamento | B12: ='Respostas ao formulário 1'!L26 -> 440V | C12: Fusível | D12: ='Respostas ao formulário 1'!H26 -> NH 2 710A 690V
A13: Driver 1 | B13: ='Respostas ao formulário 1'!M26 -> CFW110211T4SZ | C13: Driver 2 | D13: ='Respostas ao formulário 1'!O26 -> CFW110370T4SZ
A14: Serial | B14: ='Respostas ao formulário 1'!N26 -> 1023329962 | C14: Serial | D14: ='Respostas ao formulário 1'!P26 -> 1051050031
A16: Dados Motores
A17: Fabricante | B17: Carcaça | C17: Potência | D17: Tensão | E17: Corrente | F17: RPM | G17: FS | H17: Acionamento
A18: Weg | B18: 355 M/L | C18: ='Respostas ao formulário 1'!U26 -> 300CV | D18: ='Respostas ao formulário 1'!V26 -> 440 | E18: ='Respostas ao formulário 1'!W26 -> 343 | F18: ='Respostas ao formulário 1'!X26 -> 1790 | G18: ='Respostas ao formulário 1'!Y26 -> 1.15 | H18: ='Respostas ao formulário 1'!Z26 -> Driver 1
A19: Fabricante | B19: Carcaça | C19: Potência | D19: Tensão | E19: Corrente | F19: RPM | G19: FS | H19: Acionamento
A20: Weg | B20: 355 M/L | C20: ='Respostas ao formulário 1'!AA26 -> 250CV | D20: ='Respostas ao formulário 1'!AB26 -> 440 | E20: ='Respostas ao formulário 1'!AC26 -> 292 | F20: ='Respostas ao formulário 1'!AD26 -> 1790 | G20: ='Respostas ao formulário 1'!AE26 -> 1.25 | H20: ='Respostas ao formulário 1'!AF26 -> Driver 2
A22: Sensores
A23: Sucção | B23: Recalque | C23: Modelo Vazão
A24: ='Respostas ao formulário 1'!AU26 -> Zurich - 0 a 70 MCA | B24: ='Respostas ao formulário 1'!AV26 -> Zurich - 0 a 100 MCA | C24: ='Respostas ao formulário 1'!BA26 -> BLIT-EM

Sheet Barbosa Lage (Vazão)
B1: Dados dos Equipamentos Local: Barbosa Lage Tipo: Vazão
A5: Dados Telemetria
A6: Comunicação | B6: ='Respostas ao formulário 1'!E25 -> Rádio
A7: Redundância | B7: ='Respostas ao formulário 1'!F25 -> Sem Redundância
A8: Alimentação | B8: ='Respostas ao formulário 1'!J25 -> Weg
A9: DPS | B9: ='Respostas ao formulário 1'!G25 -> 0
A11: Dados da Estação
A12: Modelo Vazão | B12: ='Respostas ao formulário 1'!BA25 -> ML110

Sheet Bairu II
B1: Dados dos Equipamentos Local: Bairu II Tipo: Elevatória de Água
A5: Dados Telemetria
A6: Comunicação | B6: ='Respostas ao formulário 1'!E24 -> Modem ABS
A7: Redundância | B7: ='Respostas ao formulário 1'!F24 -> Fibra
A8: Marca da Fonte | B8: ='Respostas ao formulário 1'!J24 -> Weg
A9: DPS | B9: ='Respostas ao formulário 1'!G24 -> Clamper
A11: Dados Inversor
A12: Acionamento | B12: ='Respostas ao formulário 1'!L24 -> 440V | C12: Fusível | D12: ='Respostas ao formulário 1'!H24 -> NH2 630A 690V
A13: Driver 1 | B13: ='Respostas ao formulário 1'!M24 -> CFW110312T4SZ | C13: Driver 2 | D13: ='Respostas ao formulário 1'!O24 -> CFW110312T4SZ
A14: Serial | B14: ='Respostas ao formulário 1'!N24 -> 1068353167 | C14: Serial | D14: ='Respostas ao formulário 1'!P24 -> 1068893017
A16: Dados Motores
A17: Fabricante | B17: Carcaça | C17: Potência | D17: Tensão | E17: Corrente | F17: RPM | G17: FS | H17: Acionamento
C18: ='Respostas ao formulário 1'!U24 -> 175CV | D18: ='Respostas ao formulário 1'!V24 -> 440V | E18: ='Respostas ao formulário 1'!W24 -> 209A | F18: ='Respostas ao formulário 1'!X24 -> 1791 | G18: ='Respostas ao formulário 1'!Y24 -> 1.25 | H18: ='Respostas ao formulário 1'!Z24 -> Driver 1
A19: Fabricante | B19: Carcaça | C19: Potência | D19: Tensão | E19: Corrente | F19: RPM | G19: FS | H19: Acionamento
C20: ='Respostas ao formulário 1'!AA24 -> 175CV | D20: ='Respostas ao formulário 1'!AB24 -> 440V | E20: ='Respostas ao formulário 1'!AC24 -> 209A | F20: ='Respostas ao formulário 1'!AD24 -> 1791 | G20: ='Respostas ao formulário 1'!AE24 -> 1.25 | H20: ='Respostas ao formulário 1'!AF24 -> Driver 2
A22: Sensores
A23: Sucção | B23: Recalque | C23: Modelo Vazão
A24: ='Respostas ao formulário 1'!AU24 -> Zurich - 0 a 70 MCA | B24: ='Respostas ao formulário 1'!AV24 -> Pressgage - 0 a 70 MCA | C24: ='Respostas ao formulário 1'!BA24 -> MV110

Sheet Bairro de Lourdes
B1: Dados dos Equipamentos Local: Bairro de Lourdes Tipo: Reservatório
A5: Dados Telemetria
A6: Comunicação | B6: ='Respostas ao formulário 1'!E23 -> Modem ABS
A7: Redundância | B7: ='Respostas ao formulário 1'!F23 -> Sem Redundância
A8: Alimentação | B8: ='Respostas ao formulário 1'!B23 -> 127V
A9: DPS | B9: ='Respostas ao formulário 1'!G23 -> Lupa
A11: Dados do Reservatório
A12: Tipo de Sensor | B12: ='Respostas ao formulário 1'!BZ23 -> Ultrassônico Nivelco - 0 a 5 m
A13: Fusível | B13: ='Respostas ao formulário 1'!H23 -> 0
A15: Dimensões
A16: Altura Total (m)
A17: 3.6
A18: Altura do 0% (4mA) (m)
A19: 0
A20: Altura do 100% (20mA) (m)
A21: 3

Sheet Assuene Ribeiro
B1: Dados dos Equipamentos Local: Assuene Ribeiro Tipo: VRP
A5: Dados Telemetria
A6: Comunicação | B6: ='Respostas ao formulário 1'!E22 -> Modem ABS
A7: Redundância | B7: ='Respostas ao formulário 1'!F22 -> Sem Redundância
A8: Alimentação | B8: ='Respostas ao formulário 1'!J22 -> Conexel
A9: DPS | B9: ='Respostas ao formulário 1'!G22 -> Clamper
A11: Dados da VRP
A12: Sensor à Jusante | B12: ='Respostas ao formulário 1'!AU22 -> Zurick - 0 a 100 MCA
A13: Sensor à Montante | B13: ='Respostas ao formulário 1'!AV22 -> Zurick - 0 a 100 MCA
A14: Modelo Vazão 1 | B14: ='Respostas ao formulário 1'!BA22 -> MV110

Sheet Ase-Grama
B1: Dados dos Equipamentos Local: Ase-Grama Tipo: Elevatória de Água
A5: Dados Telemetria
A6: Comunicação | B6: ='Respostas ao formulário 1'!E21 -> Modem LUPA
A7: Redundância | B7: ='Respostas ao formulário 1'!F21 -> Fibra
A8: Marca da Fonte | B8: ='Respostas ao formulário 1'!J21 -> Weg
A9: DPS | B9: ='Respostas ao formulário 1'!G21 -> Lupa
A11: Dados Inversor
A12: Acionamento | B12: ='Respostas ao formulário 1'!L21 -> 440V | C12: Fusível | D12: ='Respostas ao formulário 1'!H21 -> NH1 400A 690V
A13: Driver 1 | B13: ='Respostas ao formulário 1'!M21 -> CFW110370T4SZ | C13: Driver 2 | D13: ='Respostas ao formulário 1'!O21 -> CFW110370T4SZ
A14: Serial | B14: ='Respostas ao formulário 1'!N21 -> 1069895964 | C14: Serial | D14: ='Respostas ao formulário 1'!P21 -> 1051050031
A16: Dados Motores
A17: Fabricante | B17: Carcaça | C17: Potência | D17: Tensão | E17: Corrente | F17: RPM | G17: FS | H17: Acionamento
C18: ='Respostas ao formulário 1'!U21 -> 250CV | D18: ='Respostas ao formulário 1'!V21 -> 440V | E18: ='Respostas ao formulário 1'!W21 -> 292A | F18: ='Respostas ao formulário 1'!X21 -> 1790 | G18: ='Respostas ao formulário 1'!Y21 -> 1.25 | H18: ='Respostas ao formulário 1'!Z21 -> Driver 1
A19: Fabricante | B19: Carcaça | C19: Potência | D19: Tensão | E19: Corrente | F19: RPM | G19: FS | H19: Acionamento
C20: ='Respostas ao formulário 1'!AA21 -> 250CV | D20: ='Respostas ao formulário 1'!AB21 -> 440V | E20: ='Respostas ao formulário 1'!AC21 -> 292A | F20: ='Respostas ao formulário 1'!AD21 -> 1790 | G20: ='Respostas ao formulário 1'!AE21 -> 1.25 | H20: ='Respostas ao formulário 1'!AF21 -> Driver 2
A22: Sensores
A23: Sucção | B23: Recalque | C23: Modelo Vazão
A24: ='Respostas ao formulário 1'!AU21 -> Zurich - 0 a 70 MCA | B24: ='Respostas ao formulário 1'!AV21 -> Conect - 0 a 200 MCA | C24: ='Respostas ao formulário 1'!BA21 -> MV110

Sheet Antônio de Castro
B1: Dados dos Equipamentos Local: Antônio de Castro Tipo: VRP
A5: Dados Telemetria
A6: Comunicação | B6: ='Respostas ao formulário 1'!E20 -> Modem ABS
A7: Redundância | B7: ='Respostas ao formulário 1'!F20 -> Sem Redundância
A8: Alimentação | B8: ='Respostas ao formulário 1'!J20 -> Weidmuller
A9: DPS | B9: ='Respostas ao formulário 1'!G20 -> Lupa
A11: Dados da VRP
A12: Sensor à Jusante | B12: ='Respostas ao formulário 1'!AU20 -> 0 - 200 MCA
A13: Sensor à Montante | B13: ='Respostas ao formulário 1'!AV20 -> 0 - 200 MCA
A14: Modelo Vazão 1 | B14: ='Respostas ao formulário 1'!BA20 -> MV110
A15: Modelo Vazão 2 | B15: ='Respostas ao formulário 1'!BJ20 -> MAG 5000

Sheet Amazonas (Reservatório)
B1: Dados dos Equipamentos Local: Amazonas Tipo: Reservatório
A5: Dados Telemetria
A6: Comunicação | B6: ='Respostas ao formulário 1'!E19 -> Modem ABS
A7: Redundância | B7: ='Respostas ao formulário 1'!F19 -> Sem Redundância
A8: Alimentação | B8: ='Respostas ao formulário 1'!B19 -> 127V
A9: DPS | B9: ='Respostas ao formulário 1'!G19 -> Clamper
A11: Dados do Reservatório
A12: Tipo de Sensor | B12: ='Respostas ao formulário 1'!BZ19 -> Hidroestático
A13: Fusível | B13: ='Respostas ao formulário 1'!H19 -> 0
A15: Dimensões
A16: Altura Total (m)
A18: Altura do 0% (4mA) (m)
A19: 0
A20: Altura do 100% (20mA) (m)

Sheet Amazonas
B1: Dados dos Equipamentos Local: Amazonas Tipo: Elevatória de Água
A5: Dados Telemetria
A6: Comunicação | B6: ='Respostas ao formulário 1'!E18 -> Modem LUPA
A7: Redundância | B7: ='Respostas ao formulário 1'!F18 -> Sem Redundância
A8: Marca da Fonte | B8: ='Respostas ao formulário 1'!J18 -> LR Informática
A9: DPS | B9: ='Respostas ao formulário 1'!G18 -> Lupa
A11: Dados Inversor
A12: Acionamento | B12: ='Respostas ao formulário 1'!L18 -> 220V
A13: Fusível | B13: ='Respostas ao formulário 1'!H18 -> NH00 80A 690V
A14: Driver 1 | B14: ='Respostas ao formulário 1'!M18 -> CFW110054T2OFAZ
A15: Serial | B15: ='Respostas ao formulário 1'!N18 -> 1039442998
A17: Dados Motores
A18: Fabricante | B18: Carcaça | C18: Potência | D18: Tensão | E18: Corrente | F18: RPM | G18: FS | H18: Acionamento
A19: Weg | B19: 132M | C19: ='Respostas ao formulário 1'!U18 -> 12.5CV | D19: ='Respostas ao formulário 1'!V18 -> 220V | E19: ='Respostas ao formulário 1'!W18 -> 29.8A | F19: ='Respostas ao formulário 1'!X18 -> 3530 | G19: ='Respostas ao formulário 1'!Y18 -> 1.25 | H19: ='Respostas ao formulário 1'!Z18 -> Driver 1
A20: Fabricante | B20: Carcaça | C20: Potência | D20: Tensão | E20: Corrente | F20: RPM | G20: FS | H20: Acionamento
A21: Weg | B21: 132M | C21: ='Respostas ao formulário 1'!AA18 -> 12.5CV | D21: ='Respostas ao formulário 1'!AB18 -> 220V | E21: ='Respostas ao formulário 1'!AC18 -> 29.8A | F21: ='Respostas ao formulário 1'!AD18 -> 3530 | G21: ='Respostas ao formulário 1'!AE18 -> 1.25 | H21: ='Respostas ao formulário 1'!AF18 -> Driver 1
A23: Sensores
A24: Sucção | B24: Recalque | C24: Modelo Vazão
A25: ='Respostas ao formulário 1'!AU18 -> Zurich - 0 a 70 MCA | B25: ='Respostas ao formulário 1'!AV18 -> Zurich - 0 a 100 MCA | C25: ='Respostas ao formulário 1'!BA18 -> MV110

Sheet Alvim (Elevatória)
B1: Dados dos Equipamentos Local: Alvim Tipo: Elevatória de Água
A5: Dados Telemetria
A6: Comunicação | B6: ='Respostas ao formulário 1'!E17 -> Modem ABS
A7: Redundância | B7: ='Respostas ao formulário 1'!F17 -> Sem Redundância
A8: Marca da Fonte | B8: ='Respostas ao formulário 1'!J17 -> Conexel
A9: DPS | B9: ='Respostas ao formulário 1'!G17 -> Clamper
A11: Dados Inversor
A12: Acionamento | B12: ='Respostas ao formulário 1'!L17 -> 220V
A13: Fusível | B13: ='Respostas ao formulário 1'!H17 -> NH00 63A 690V
A14: Driver 1 | B14: ='Respostas ao formulário 1'!M17 -> CFW110024T2OFAZ
A15: Serial | B15: ='Respostas ao formulário 1'!N17 -> 1067450220
A17: Dados Motores
A18: Fabricante | B18: Carcaça | C18: Potência | D18: Tensão | E18: Corrente | F18: RPM | G18: FS | H18: Acionamento
C19: ='Respostas ao formulário 1'!U17 -> 7.5 CV | D19: ='Respostas ao formulário 1'!V17 -> 220V | E19: ='Respostas ao formulário 1'!W17 -> 19.4A | F19: ='Respostas ao formulário 1'!X17 -> 3515 | G19: ='Respostas ao formulário 1'!Y17 -> 1.25 | H19: ='Respostas ao formulário 1'!Z17 -> Driver 1
A20: Fabricante | B20: Carcaça | C20: Potência | D20: Tensão | E20: Corrente | F20: RPM | G20: FS | H20: Acionamento
C21: ='Respostas ao formulário 1'!AA17 -> 7.5CV | D21: ='Respostas ao formulário 1'!AB17 -> 220V | E21: ='Respostas ao formulário 1'!AC17 -> 19.4A | F21: ='Respostas ao formulário 1'!AD17 -> 3515 | G21: ='Respostas ao formulário 1'!AE17 -> 1.25 | H21: ='Respostas ao formulário 1'!AF17 -> Driver 1
A23: Sensores
A24: Sucção | B24: Recalque | C24: Modelo Vazão
A25: ='Respostas ao formulário 1'!AU17 -> Sem sucção | B25: ='Respostas ao formulário 1'!AV17 -> Zurich - 0 a 200 MCA | C25: ='Respostas ao formulário 1'!BA17 -> 0

Sheet Alto Santo  AntônioRetiro
B1: Dados dos Equipamentos Local: Alto Santo Antônio Tipo: Elevatória de Água
A5: Dados Telemetria
A6: Comunicação | B6: ='Respostas ao formulário 1'!E16 -> 0
A7: Redundância | B7: ='Respostas ao formulário 1'!F16 -> 0
A8: Marca da Fonte | B8: ='Respostas ao formulário 1'!J16 -> 0
A9: DPS | B9: ='Respostas ao formulário 1'!G16 -> 0
A11: Dados Inversor
A12: Acionamento | B12: ='Respostas ao formulário 1'!L16 -> 220V | C12: Fusível | D12: ='Respostas ao formulário 1'!H16 -> NH1 200A 500V
A13: Driver 1 | B13: ='Respostas ao formulário 1'!M16 -> Soft Ssw 03 | C13: Driver 2 | D13: ='Respostas ao formulário 1'!O16 -> CFW110105T2OFAZ
A14: Serial | B14: ='Respostas ao formulário 1'!N15 -> 0 | C14: Serial | D14: ='Respostas ao formulário 1'!P16 -> 1035540477
A16: Dados Motores
A17: Fabricante | B17: Carcaça | C17: Potência | D17: Tensão | E17: Corrente | F17: RPM | G17: FS | H17: Acionamento
C18: ='Respostas ao formulário 1'!U16 -> 40CV | D18: ='Respostas ao formulário 1'!V16 -> 220V | E18: ='Respostas ao formulário 1'!W16 -> 99A | F18: ='Respostas ao formulário 1'!X16 -> 3560 | G18: ='Respostas ao formulário 1'!Y16 -> 1.25 | H18: ='Respostas ao formulário 1'!Z16 -> Driver 1
A19: Fabricante | B19: Carcaça | C19: Potência | D19: Tensão | E19: Corrente | F19: RPM | G19: FS | H19: Acionamento
C20: ='Respostas ao formulário 1'!AA16 -> 40CV | D20: ='Respostas ao formulário 1'!AB16 -> 220V | E20: ='Respostas ao formulário 1'!AC16 -> 99A | F20: ='Respostas ao formulário 1'!AD16 -> 3560 | G20: ='Respostas ao formulário 1'!AE16 -> 1.25 | H20: ='Respostas ao formulário 1'!AF16 -> Driver 2
A22: Sensores
A23: Sucção | B23: Recalque | C23: Modelo Vazão
A24: ='Respostas ao formulário 1'!AU16 -> 0 | B24: ='Respostas ao formulário 1'!AV16 -> Zurich - 0 a 200 MCA | C24: ='Respostas ao formulário 1'!BA16 -> MV110

Sheet Alto Santo Antonio (Reservatóri
B1: Dados dos Equipamentos Local: Alto Santo Antônio Tipo: Reservatório com Elevatória
A5: Dados Telemetria
A6: Comunicação | B6: ='Respostas ao formulário 1'!E15 -> Modem ABS
A7: Redundância | B7: ='Respostas ao formulário 1'!F15 -> Sem Redundância
A8: Marca da Fonte | B8: ='Respostas ao formulário 1'!J15 -> Weidmuller
A9: DPS | B9: ='Respostas ao formulário 1'!G15 -> Lupa
A11: Dados Inversor
A12: Acionamento | B12: ='Respostas ao formulário 1'!L16 -> 220V | C12: Fusível | D12: ='Respostas ao formulário 1'!H16 -> NH1 200A 500V
A13: Driver 1 | B13: ='Respostas ao formulário 1'!M16 -> Soft Ssw 03 | C13: Driver 2 | D13: ='Respostas ao formulário 1'!O16 -> CFW110105T2OFAZ
A14: Serial | B14: ='Respostas ao formulário 1'!N16 -> 0 | C14: Serial | D14: ='Respostas ao formulário 1'!P16 -> 1035540477
A16: Dados Motores
A17: Fabricante | B17: Carcaça | C17: Potência | D17: Tensão | E17: Corrente | F17: RPM | G17: FS | H17: Acionamento
C18: ='Respostas ao formulário 1'!U15 -> 3CV | D18: ='Respostas ao formulário 1'!V15 -> 220V | E18: ='Respostas ao formulário 1'!W15 -> 8.42A | F18: ='Respostas ao formulário 1'!X15 -> 3465 | G18: ='Respostas ao formulário 1'!Y15 -> 1.15 | H18: ='Respostas ao formulário 1'!Z15 -> Driver 1
A19: Fabricante | B19: Carcaça | C19: Potência | D19: Tensão | E19: Corrente | F19: RPM | G19: FS | H19: Acionamento
C20: ='Respostas ao formulário 1'!AA15 -> 3CV | D20: ='Respostas ao formulário 1'!AB15 -> 220V | E20: ='Respostas ao formulário 1'!AC15 -> 8.42A | F20: ='Respostas ao formulário 1'!AD15 -> 3465 | G20: ='Respostas ao formulário 1'!AE15 -> 1.15 | H20: ='Respostas ao formulário 1'!AF15 -> Driver 1
A22: Sensores
A23: Sucção | B23: Recalque | C23: Modelo Vazão
A24: ='Respostas ao formulário 1'!AU15 -> SMAR - Janela | B24: ='Respostas ao formulário 1'!AV15 -> 0 | C24: ='Respostas ao formulário 1'!BA15 -> 0
A26: Dados do Reservatório
A27: Tipo de Sensor | B27: ='Respostas ao formulário 1'!BZ15 -> Pressão
A29: Dimensões
A30: Altura Total (m)
A31: 3.87
A32: Altura do 0% (4mA) (m)
A33: 0
A34: Altura do 100% (20mA) (m)
A35: 3.17

Sheet Alto dos Pinheiros (Elevatória)
B1: Dados dos Equipamentos Local: Alto dos Pinheiros Tipo: Elevatória de Água
